# 错误处理

    // 错误处理是响应错误以及从错误中恢复的过程
    // 支持抛出、捕获、传递和操作可恢复错误

## 表示与抛出错误
    // 错误用遵循 Error 协议的类型的值来表示
    // 这个空协议表明该类型可以用于错误处理
    // 枚举类型尤为适合构建一组相关的错误状态
    // 枚举的关联值还可以提供错误状态的额外信息
    enum FileError: Error {
        case invalidFileName            // 无效的文件名称
        case invalidFileType            // 无效的文件类型
        case invalidFileSize(size: Int) // 无效的文件尺寸
    }

    struct SomeError: Error {
        let name: String
        init(name: String) {
            self.name = name
        }
    }

    // 抛出错误
    // throw FileError.invalidFileName
    // throw FileError.invalidFileSize(size: 1024)

## 处理错误
    // 有 4 种处理错误的方式
    // 1 可以把函数抛出的错误传递给调用此函数的代码
    // 2 用 do-catch 语句处理错误
    // 3 将错误作为可选类型处理
    // 4 断言此错误根本不会发生
    // 捕获错误
    // 使用 try
    // 或者 try?
    // 或者 try!

    // 注意
    // 错误处理并不涉及解除调用栈
    // 这是一个计算代价高昂的过程
    // 就此而言 throw 语句的性能特性是可以和 return 语句相媲美的

### 用 throwing 函数传递错误
    // 在函数声明的参数之后加上 throws 关键字
    // 注意
    // 只有 throwing 函数可以传递错误
    // 任何在某个非 throwing 函数内部抛出的错误只能在函数内部处理
    class FileManager {
        var fileName: String
        
        // 构造器能像 throwing 函数一样传递错误
        init(fileName: String) throws {
            guard fileName.count > 0 else {
                throw FileError.invalidFileName
            }
            self.fileName = fileName
        }
        
        // 用 throwing 函数传递错误
        func readFile(fileName: String) throws -> String {
            guard fileName.count > 0 else {
                throw FileError.invalidFileName
            }
            return "abc"
        }
    }

    // 方法可能抛出错误
    // 所以在调用的时候在前面加 try 关键字
    var fileManager = try FileManager(fileName: "a.txt")
    try print(fileManager.readFile(fileName: "b.txt"))

### 用 Do-Catch 处理错误
    // 可以使用一个 do-catch 语句运行一段闭包代码来处理错误
    // 如果在 do 子句中的代码抛出了一个错误
    // 这个错误会与 catch 子句做匹配从而决定哪条子句能处理它
    // 在 catch 后面写一个匹配模式来表明这个子句能处理什么样的错误
    // 如果一条 catch 子句没有指定匹配模式
    // 那么这条子句可以匹配任何错误
    // 并且把错误绑定到一个名字为 error 的局部常量

    do {
        try expression
        statements
    } catch pattern 1 {
        statements
    } catch pattern 2 where condition {
        statements
    } catch pattern 3, pattern 4 where condition {
        statements
    } catch {
        statements
    }

    do {
        print("do throw a error:")
        // throw FileError.invalidFileName
        // throw FileError.invalidFileType
        // throw FileError.invalidFileSize(size: 50)
        // throw FileError.invalidFileSize(size: 200)
        // throw FileError.invalidFileSize(size: 100)
        
        throw SomeError(name: "SomeErrorName")
        
    } catch FileError.invalidFileName {
        print("catch FileError.invalidFileName...")

    } catch FileError.invalidFileName, FileError.invalidFileType {
        print("catch FileError.invalidFileName or FileError.invalidFileType...")

    } catch FileError.invalidFileSize(let theSize) where theSize < 100 {
        print("catch FileError.invalidFileSize where size < 100 size = \(theSize)...")

    } catch FileError.invalidFileSize(let theSize) where theSize > 100 {
        print("catch FileError.invalidFileSize where size > 100 size = \(theSize)...")

    } catch is FileError {
        print("catch FileError...")
        
    } catch {
        print("catch other error: \(error)")
    }

### 将错误转换成可选值
    // 可以使用 try? 通过将错误转换成一个可选值来处理错误
    // 如果是在计算 try? 表达式时抛出错误，该表达式的结果就为 nil
    func someFunction() throws -> Int {
        // throw SomeError(name: "someFunction")
        return 100
    }

    // x 和 y 等价
    var x = try? someFunction()
    var y: Int?
    do {
        y = try someFunction()
    } catch {
        y = nil
    }

    print(x)
    print(y)

### 禁用错误传递
    // 有时知道某个 throwing 函数实际上在运行时是不会抛出错误的
    // 在这种情况下可以在表达式前面写 try! 来禁用错误传递
    // 这会把调用包装在一个不会有错误抛出的运行时断言中
    // 如果真的抛出了错误会得到一个运行时错误
    var z = try! someFunction()
    print(z)

## 指定清理操作
    // 可以使用 defer 语句在即将离开当前代码块时执行一系列语句
    // 该语句能执行一些必要的清理工作
    // 不管是以何种方式离开当前代码块的
    // 无论是由于抛出错误而离开
    // 或是由于诸如 return、break 的语句

    // defer 语句将代码的执行延迟到当前的作用域退出之前
    // 该语句由 defer 关键字和要被延迟执行的语句组成
    // 延迟执行的语句不能包含任何控制转移语句
    // 例如 break、return 语句，或是抛出一个错误
    // 延迟执行的操作会按照它们声明的顺序从后往前执行
    // 也就是说:
    // 第一条 defer 语句中的代码最后才执行
    // 第二条 defer 语句中的代码倒数第二个执行
    // 最后一条语句会第一个执行
    // 注意
    // defer 需要放在退出语句的前面才执行
    func processFile() throws {
        print("begin..")
        defer {
            print("111-a")
            print("111-b")
            print("111-c")
        }
        defer {
            print("222-a")
            print("222-b")
            print("222-c")
        }
        defer {
            print("333-a")
            print("333-b")
            print("333-c")
        }
        // 放在defer后面才行
        // throw SomeError(name: "processFile")
        return
        print("end..")
    }

    try processFile()

## 完
